<?xml version="1.0" ?>
<robot name="window">
	<link name="base"/>
	<link name="link_0">
		<visual name="out-frame">
			<origin xyz="0 0 0"/>
			<geometry>
				<mesh filename="texture_dae/untitled.dae" scale="0.5 0.5 0.5"/>
			</geometry>
		</visual>
		<collision>
			<origin xyz="0 0 0"/>
			<geometry>
				<mesh filename="texture_dae/untitled.dae" scale="0.5 0.5 0.5"/>
			</geometry>
		</collision>
	</link>
	<joint name="joint_0" type="fixed">
		<origin rpy="1.570796326794897 0 -1.570796326794897" xyz="0 0 0"/>
		<child link="link_0"/>
		<parent link="base"/>
	</joint>
	<link name="link_1">
		<visual name="surf-board">
			<origin xyz="0.30546158315543975 -0.5833843402065071 0"/>
			<geometry>
				<mesh filename="texture_dae/untitled1.dae" scale="0.5 0.5 0.5"/>
			</geometry>
		</visual>
		<collision>
			<origin xyz="0.30546158315543975 -0.5833843402065071 0"/>
			<geometry>
				<mesh filename="texture_dae/untitled1.dae" scale="0.5 0.5 0.5"/>
			</geometry>
		</collision>
	</link>
	<joint name="joint_1" type="revolute">
		<origin xyz="-0.30546158315543975 0.5833843402065071 0"/>
		<axis xyz="0 -1 0"/>
		<child link="link_1"/>
		<parent link="link_0"/>
		<limit lower="0" upper="1.5079644737231006"/>
	</joint>
	<link name="link_2">
		<visual name="handle">
			<origin xyz="0 0 0"/>
			<geometry>
				<mesh filename="texture_dae/9969525-handle.dae" scale="1.2798660714082932 1.2798660714082932 1.2798660714082932"/>
			</geometry>
		</visual>
		<collision>
			<origin xyz="0 0 0"/>
			<geometry>
				<mesh filename="texture_dae/9969525-handle.dae" scale="1.2798660714082932 1.2798660714082932 1.2798660714082932"/>
			</geometry>
		</collision>
	</link>
	<joint name="joint_2" type="revolute">
		<origin xyz="0 0 0"/>
		<child link="link_2"/>
		<parent link="link_3"/>
		<axis xyz="0 0 1"/>
		<limit lower="0" upper="1.5079644737231006"/>
	</joint>
	<link name="link_3">
		<visual name="lock">
			<origin xyz="0 0 0"/>
			<geometry>
				<mesh filename="texture_dae/9969525-lock.dae" scale="1.2798660714082932 1.2798660714082932 1.2798660714082932"/>
			</geometry>
		</visual>
		<collision>
			<origin xyz="0 0 0"/>
			<geometry>
				<mesh filename="texture_dae/9969525-lock.dae" scale="1.2798660714082932 1.2798660714082932 1.2798660714082932"/>
			</geometry>
		</collision>
	</link>
	<joint name="joint_3" type="fixed">
		<origin xyz="0.57960002006893 -0.5833843402065071 0.028971898873196622"/>
		<child link="link_3"/>
		<parent link="link_1"/>
	</joint>
</robot>
