<?xml version="1.0" ?>
<robot name="window">
	<link name="base"/>
	<link name="link_0">
		<visual name="out-frame">
			<origin xyz="0 0 0"/>
			<geometry>
				<mesh filename="texture_dae/untitled.dae" scale="1 1 1"/>
			</geometry>
		</visual>
		<collision>
			<origin xyz="0 0 0"/>
			<geometry>
				<mesh filename="texture_dae/untitled.dae" scale="1 1 1"/>
			</geometry>
		</collision>
	</link>
	<joint name="joint_0" type="fixed">
		<origin rpy="1.570796326794897 0 -1.570796326794897" xyz="0 0 0"/>
		<child link="link_0"/>
		<parent link="base"/>
	</joint>
	<link name="link_1">
		<visual name="surf-board">
			<origin xyz="0.3051365797779531 -0.42271840093149793 0"/>
			<geometry>
				<mesh filename="texture_dae/untitled1.dae" scale="1 1 1"/>
			</geometry>
		</visual>
		<collision>
			<origin xyz="0.3051365797779531 -0.42271840093149793 0"/>
			<geometry>
				<mesh filename="texture_dae/untitled1.dae" scale="1 1 1"/>
			</geometry>
		</collision>
	</link>
	<joint name="joint_1" type="revolute">
		<origin xyz="-0.3051365797779531 0.42271840093149793 0"/>
		<axis xyz="0 -1 0"/>
		<child link="link_1"/>
		<parent link="link_0"/>
		<limit lower="0" upper="1.5079644737231006"/>
	</joint>
	<link name="link_2">
		<visual name="handle">
			<origin xyz="0 0 0"/>
			<geometry>
				<mesh filename="texture_dae/9969503-handle.dae" scale="0.8982036074989415 0.8982036074989415 0.8982036074989415"/>
			</geometry>
		</visual>
		<collision>
			<origin xyz="0 0 0"/>
			<geometry>
				<mesh filename="texture_dae/9969503-handle.dae" scale="0.8982036074989415 0.8982036074989415 0.8982036074989415"/>
			</geometry>
		</collision>
	</link>
	<joint name="joint_2" type="revolute">
		<origin xyz="0 0 0"/>
		<child link="link_2"/>
		<parent link="link_3"/>
		<axis xyz="0 0 1"/>
		<limit lower="0" upper="1.5079644737231006"/>
	</joint>
	<link name="link_3">
		<visual name="lock">
			<origin xyz="0 0 0"/>
			<geometry>
				<mesh filename="texture_dae/9969503-lock.dae" scale="0.8982036074989415 0.8982036074989415 0.8982036074989415"/>
			</geometry>
		</visual>
		<collision>
			<origin xyz="0 0 0"/>
			<geometry>
				<mesh filename="texture_dae/9969503-lock.dae" scale="0.8982036074989415 0.8982036074989415 0.8982036074989415"/>
			</geometry>
		</collision>
	</link>
	<joint name="joint_3" type="fixed">
		<origin xyz="0.5650000618394104 -0.42271840093149793 0.015310818353232131"/>
		<child link="link_3"/>
		<parent link="link_1"/>
	</joint>
</robot>
